<?xml version="1.0"?>
<robot name="2dof_arm" xmlns:xacro="http://www.ros.org/wiki/xacro">

  <!-- Base Link -->
  <link name="base_link">
    <inertial>
      <mass value="1.0"/>
      <origin xyz="0 0 0" rpy="0 0 0"/>
      <inertia ixx="0.01" iyy="0.01" izz="0.01" ixy="0" ixz="0" iyz="0"/>
    </inertial>
    <visual>
      <geometry><cylinder length="0.1" radius="0.05"/></geometry>
      <material name="base_material">
        <color rgba="0.3 0.3 0.3 1"/>
      </material>
    </visual>
    <collision>
      <geometry><cylinder length="0.1" radius="0.05"/></geometry>
    </collision>
  </link>

  <!-- Joint 1 -->
  <joint name="joint1" type="revolute">
    <parent link="base_link"/>
    <child link="link1"/>
    <origin xyz="0 0 0.05" rpy="0 0 0"/>
    <axis xyz="0 0 1"/>
    <limit effort="10.0" velocity="1.0" lower="-1.57" upper="1.57"/>
  </joint>

  <!-- Link 1 -->
  <link name="link1">
    <inertial>
      <mass value="0.8"/>
      <origin xyz="0 0 0" rpy="0 0 0"/>
      <inertia ixx="0.005" iyy="0.005" izz="0.005" ixy="0" ixz="0" iyz="0"/>
    </inertial>
    <visual>
      <geometry><box size="0.3 0.05 0.05"/></geometry>
      <material name="link1_material">
        <color rgba="0.6 0.2 0.2 1"/>
      </material>
    </visual>
    <collision>
      <geometry><box size="0.3 0.05 0.05"/></geometry>
    </collision>
  </link>

  <!-- Joint 2 -->
  <joint name="joint2" type="revolute">
    <parent link="link1"/>
    <child link="link2"/>
    <origin xyz="0.15 0 0" rpy="0 0 0"/>
    <axis xyz="0 0 1"/>
    <limit effort="10.0" velocity="1.0" lower="-1.57" upper="1.57"/>
  </joint>

  <!-- Link 2 -->
  <link name="link2">
    <inertial>
      <mass value="0.5"/>
      <origin xyz="0 0 0" rpy="0 0 0"/>
      <inertia ixx="0.003" iyy="0.003" izz="0.003" ixy="0" ixz="0" iyz="0"/>
    </inertial>
    <visual>
      <geometry><box size="0.3 0.05 0.05"/></geometry>
      <material name="link2_material">
        <color rgba="0.2 0.2 0.6 1"/>
      </material>
    </visual>
    <collision>
      <geometry><box size="0.3 0.05 0.05"/></geometry>
    </collision>
  </link>
</robot>
